<?xml version="1.0" encoding="utf-8"?>
<!-- This URDF was automatically created by SolidWorks to URDF Exporter! Originally created by Stephen Brawner (brawner@gmail.com) 
     Commit Version: 1.6.0-4-g7f85cfe  Build Version: 1.6.7995.38578
     For more information, please see http://wiki.ros.org/sw_urdf_exporter -->
<robot name="JC04">

  <link name="base_link" />
  <joint name="base_joint" type="fixed">
    <origin xyz="0.0 0.0 0.0" rpy="0.0 0.0 0.0"/>
    <parent link="base_link"/>
    <child link="robot_base"/>
  </joint>

  <link name="robot_base">
    <inertial>
      <origin
        xyz="0.00224248924885996 -0.0002327036022796 0.00387000358313808"
        rpy="0 0 0" />
      <mass
        value="8.13037365577089" />
      <inertia
        ixx="0.0159928228906131"
        ixy="6.14120596643724E-06"
        ixz="5.42564592074981E-05"
        iyy="0.0151761586207989"
        iyz="-9.14986154096099E-07"
        izz="0.0148933416798849" />
    </inertial>
    <visual>
      <origin
        xyz="0 0 0"
        rpy="0 0 0" />
      <geometry>
        <mesh
          filename="package://jc04_desc/meshes/robot_base.STL" />
      </geometry>
      <material
        name="">
        <color
          rgba="0.698039215686274 0.698039215686274 0.698039215686274 1" />
      </material>
    </visual>
    <collision>
      <origin
        xyz="0 0 0"
        rpy="0 0 0" />
      <geometry>
        <mesh
          filename="package://jc04_desc/meshes/robot_base.STL" />
      </geometry>
    </collision>
  </link>
  <link name="battery_link">
    <inertial>
      <origin
        xyz="0.00147352319103189 -0.00983442379526532 -0.0960919883168707"
        rpy="0 0 0" />
      <mass
        value="4.11268900448766" />
      <inertia
        ixx="0.00274295134808096"
        ixy="4.94653019700017E-09"
        ixz="-1.82905940452392E-07"
        iyy="0.00402012516832071"
        iyz="-4.65100565927656E-11"
        izz="0.00412791323709621" />
    </inertial>
    <visual>
      <origin
        xyz="0 0 0"
        rpy="0 0 0" />
      <geometry>
        <mesh
          filename="package://jc04_desc/meshes/battery_link.STL" />
      </geometry>
      <material
        name="">
        <color
          rgba="0.69804 0.69804 0.69804 1" />
      </material>
    </visual>
    <collision>
      <origin
        xyz="0 0 0"
        rpy="0 0 0" />
      <geometry>
        <mesh
          filename="package://jc04_desc/meshes/battery_link.STL" />
      </geometry>
    </collision>
  </link>
  <joint name="battery_joint" type="fixed">
    <origin
      xyz="0 0 0"
      rpy="0 0 0" />
    <parent
      link="robot_base" />
    <child
      link="battery_link" />
  </joint>
  <link  name="imu_link">
    <inertial>
      <origin xyz="0.0 0.0 0.0" rpy="0.0 0.0 0.0"></origin>
      <mass value="0.0"></mass>
      <inertia ixx="0.0" ixy="0.0" ixz="0.0" iyy="0.0" iyz="0.0" izz="0.0"></inertia>
    </inertial>
    <visual>
      <origin xyz="0.0 0.0 0.0" rpy="0.0 0.0 0.0"></origin>
      <geometry>
        <box size="0.02 0.02 0.01"></box>
      </geometry>
      <material name="yellow">
        <color rgba="1 1 0 1" />
      </material>
    </visual>
    <collision>
      <origin xyz="0.0 0.0 0.0" rpy="0.0 0.0 0.0"></origin>
      <geometry>
        <box size="0.02 0.02 0.01"></box>
      </geometry>
    </collision>
  </link>
  <joint name="imu_joint" type="fixed">
    <origin xyz="0.03 0.0 0.005" rpy="0.0 0.0 0.0"/>
    <parent link="robot_base"/>
    <child link="imu_link"/>
  </joint>
  <link name="head_link">
    <inertial>
      <origin
        xyz="0.0147528571763334 5.93865185759372E-05 0.269054824173857"
        rpy="0 0 0" />
      <mass
        value="1.07915389231332" />
      <inertia
        ixx="0.00617840504390172"
        ixy="6.63618603984813E-07"
        ixz="8.05961885787929E-05"
        iyy="0.00384349678386552"
        iyz="1.82283227561951E-07"
        izz="0.00412518659567823" />
    </inertial>
    <visual>
      <origin
        xyz="0 0 0"
        rpy="0 0 0" />
      <geometry>
        <mesh
          filename="package://jc04_desc/meshes/head_link.STL" />
      </geometry>
      <material
        name="">
        <color
          rgba="0.698039215686274 0.698039215686274 0.698039215686274 1" />
      </material>
    </visual>
    <collision>
      <origin
        xyz="0 0 0"
        rpy="0 0 0" />
      <geometry>
        <mesh
          filename="package://jc04_desc/meshes/head_link.STL" />
      </geometry>
    </collision>
  </link>
  <joint name="head_joint" type="fixed">
    <origin
      xyz="0 0 0"
      rpy="0 0 0" />
    <parent
      link="robot_base" />
    <child
      link="head_link" />
    <axis
      xyz="0 0 0" />
  </joint>
  <link name="robot_base_casing_link">
    <inertial>
      <origin
        xyz="-0.00648045280843108 -3.88049102908214E-05 0.0631447822592831"
        rpy="0 0 0" />
      <mass
        value="2.87254380293238" />
      <inertia
        ixx="0.0599323667037276"
        ixy="1.20208759292282E-06"
        ixz="-0.000153944998947079"
        iyy="0.0334302508480915"
        iyz="-3.70030621209433E-06"
        izz="0.0321772188716389" />
    </inertial>
    <visual>
      <origin
        xyz="0 0 0"
        rpy="0 0 0" />
      <geometry>
        <mesh
          filename="package://jc04_desc/meshes/robot_base_casing_link.STL" />
      </geometry>
      <material
        name="">
        <color
          rgba="0.698039215686274 0.698039215686274 0.698039215686274 1" />
      </material>
    </visual>
    <collision>
      <origin
        xyz="0 0 0"
        rpy="0 0 0" />
      <geometry>
        <mesh
          filename="package://jc04_desc/meshes/robot_base_casing_link.STL" />
      </geometry>
    </collision>
  </link>
  <joint name="robot_base_casing_joint" type="fixed">
    <origin
      xyz="0 0 0"
      rpy="0 0 0" />
    <parent
      link="robot_base" />
    <child
      link="robot_base_casing_link" />
    <axis
      xyz="0 0 0" />
  </joint>


  <link name="right_hip_pitch_link">
    <inertial>
      <origin
        xyz="8.3149E-06 0.013974 -0.21713"
        rpy="0 0 0" />
      <mass
        value="2.2497" />
      <inertia
        ixx="0.014319"
        ixy="-1.0157E-07"
        ixz="1.4397E-06"
        iyy="0.016227"
        iyz="-7.2097E-05"
        izz="0.0026066" />
    </inertial>
    <visual>
      <origin
        xyz="0 0 0"
        rpy="0 0 0" />
      <geometry>
        <mesh
          filename="package://jc04_desc/meshes/right_hip_pitch_link.STL" />
      </geometry>
      <material
        name="">
        <color
          rgba="0.898039215686275 0.917647058823529 0.929411764705882 1" />
      </material>
    </visual>
    <collision>
      <origin
        xyz="0 0 0"
        rpy="0 0 0" />
      <geometry>
        <mesh
          filename="package://jc04_desc/meshes/right_hip_pitch_link.STL" />
      </geometry>
    </collision>
  </link>
  <joint name="right_hip_pitch" type="revolute">
    <origin
      xyz="0 -0.1205 -0.098"
      rpy="0 0 0" />
    <parent
      link="robot_base" />
    <child
      link="right_hip_pitch_link" />
    <axis
      xyz="0 1 0" />
    <limit
      lower="-1.5708"
      upper="1.5708"
      effort="100.0"
      velocity="100.0" />
  </joint>
  <link name="right_knee_pitch_link">
    <inertial>
      <origin
        xyz="-0.0370926236175024 0.0102934790640934 -0.118658382266853"
        rpy="0 0 0" />
      <mass
        value="0.7580372463795" />
      <inertia
        ixx="0.00391729912353151"
        ixy="-2.74945911459871E-09"
        ixz="7.96651918764416E-15"
        iyy="0.00469716796826954"
        iyz="-0.000585098402656396"
        izz="0.00138299752551483" />
    </inertial>
    <visual>
      <origin
        xyz="0 0 0"
        rpy="0 0 0" />
      <geometry>
        <mesh
          filename="package://jc04_desc/meshes/right_knee_pitch_link.STL" />
      </geometry>
      <material
        name="">
        <color
          rgba="0.898039215686275 0.917647058823529 0.929411764705882 1" />
      </material>
    </visual>
    <collision>
      <origin
        xyz="0 0 0"
        rpy="0 0 0" />
      <geometry>
        <mesh
          filename="package://jc04_desc/meshes/right_knee_pitch_link.STL" />
      </geometry>
    </collision>
  </link>
  <joint name="right_knee_pitch" type="revolute">
    <origin
      xyz="0 -0.0025 -0.275"
      rpy="0 0 0" />
    <parent
      link="right_hip_pitch_link" />
    <child
      link="right_knee_pitch_link" />
    <axis
      xyz="0 -1 0" />
    <limit
      lower="-1.5708"
      upper="1.5708"
      effort="100.0"
      velocity="100.0" />
  </joint>
  <link name="right_driving_wheel">
    <inertial>
      <origin
        xyz="-1.39109638608807E-07 0.000947014268736196 3.5371749776969E-06"
        rpy="0 0 0" />
      <mass
        value="0.63865544033292" />
      <inertia
        ixx="0.00125776029366537"
        ixy="-1.01616021250209E-09"
        ixz="-1.36649916006925E-10"
        iyy="0.00241337774863598"
        iyz="-4.41959293887157E-08"
        izz="0.00125808821267324" />
    </inertial>
    <visual>
      <origin
        xyz="0 0 0"
        rpy="0 0 0" />
      <geometry>
        <mesh
          filename="package://jc04_desc/meshes/right_driving_wheel.STL" />
      </geometry>
      <material
        name="">
        <color
          rgba="0.792156862745098 0.819607843137255 0.933333333333333 1" />
      </material>
    </visual>
    <collision>
      <!-- <origin xyz="0 0 0" rpy="0 0 0" />
      <geometry>
        <mesh filename="package://jc04_desc/meshes/right_driving_wheel.STL" />
      </geometry> -->
      <origin xyz="0 0 0" rpy="1.5708 0 0" />
      <geometry>
        <cylinder length="0.03" radius="0.09" />
      </geometry>
    </collision>
  </link>
  <joint name="right_wheel_joint" type="continuous">
    <origin
      xyz="0 0.0087 -0.257"
      rpy="0 0 0" />
    <parent
      link="right_knee_pitch_link" />
    <child
      link="right_driving_wheel" />
    <axis
      xyz="0 1 0" />
    <limit
      effort="100.0"
      velocity="100.0" />
  </joint>
  
  <link name="right_assist_wheel">
    <inertial>
      <origin
        xyz="2.84039565173755E-07 1.12086656206545E-08 -3.08636046530975E-06"
        rpy="0 0 0" />
      <mass
        value="0.279818859797754" />
      <inertia
        ixx="0.000330074008518429"
        ixy="-3.32026430093486E-09"
        ixz="-3.38349985088429E-09"
        iyy="0.000573286880215119"
        iyz="-3.0069665547635E-10"
        izz="0.000330039613492358" />
    </inertial>
    <visual>
      <origin
        xyz="0 0 0"
        rpy="0 0 0" />
      <geometry>
        <mesh
          filename="package://jc04_desc/meshes/right_assist_wheel.STL" />
      </geometry>
      <material
        name="">
        <color
          rgba="0.752941176470588 0.752941176470588 0.752941176470588 1" />
      </material>
    </visual>
    <collision>
      <!-- <origin xyz="0 0 0" rpy="0 0 0" />
      <geometry>
        <mesh filename="package://jc04_desc/meshes/right_assist_wheel.STL" />
      </geometry> -->
      <origin xyz="0 0 0" rpy="1.5708 0 0" />
      <geometry>
        <cylinder length="0.044" radius="0.063" />
      </geometry>
    </collision>
  </link>
  <joint name="right_assist" type="fixed">
    <origin
      xyz="-0.2 0.011 -0.13951"
      rpy="0 0 0" />
    <parent
      link="right_knee_pitch_link" />
    <child
      link="right_assist_wheel" />
    <axis
      xyz="0 0 0" />
  </joint>
  <link name="right_knee_pitch_casing_link">
    <inertial>
      <origin
        xyz="-0.0430263688335211 0.00856002595508222 -0.153630642130447"
        rpy="0 0 0" />
      <mass
        value="1.41913052433229" />
      <inertia
        ixx="0.00956530771669534"
        ixy="-1.70251359123832E-05"
        ixz="0.000917394669915206"
        iyy="0.0151465901728376"
        iyz="3.71969814245014E-05"
        izz="0.00623308905855227" />
    </inertial>
    <visual>
      <origin
        xyz="0 0 0"
        rpy="0 0 0" />
      <geometry>
        <mesh
          filename="package://jc04_desc/meshes/right_knee_pitch_casing_link.STL" />
      </geometry>
      <material
        name="">
        <color
          rgba="0.698039215686274 0.698039215686274 0.698039215686274 1" />
      </material>
    </visual>
    <collision>
      <origin
        xyz="0 0 0"
        rpy="0 0 0" />
      <geometry>
        <mesh
          filename="package://jc04_desc/meshes/right_knee_pitch_casing_link.STL" />
      </geometry>
    </collision>
  </link>
  <joint name="right_knee_pitch_casing_joint" type="fixed">
    <origin
      xyz="0 0 0"
      rpy="0 0 0" />
    <parent
      link="right_knee_pitch_link" />
    <child
      link="right_knee_pitch_casing_link" />
    <axis
      xyz="0 0 0" />
  </joint>


  <link name="left_hip_pitch_link">
    <inertial>
      <origin
        xyz="-8.3149E-06 -0.013976 -0.21713"
        rpy="0 0 0" />
      <mass
        value="2.2497" />
      <inertia
        ixx="0.014319"
        ixy="-1.0157E-07"
        ixz="-1.4397E-06"
        iyy="0.016227"
        iyz="7.2097E-05"
        izz="0.0026066" />
    </inertial>
    <visual>
      <origin
        xyz="0 0 0"
        rpy="0 0 0" />
      <geometry>
        <mesh
          filename="package://jc04_desc/meshes/left_hip_pitch_link.STL" />
      </geometry>
      <material
        name="">
        <color
          rgba="0.898039215686275 0.917647058823529 0.929411764705882 1" />
      </material>
    </visual>
    <collision>
      <origin
        xyz="0 0 0"
        rpy="0 0 0" />
      <geometry>
        <mesh
          filename="package://jc04_desc/meshes/left_hip_pitch_link.STL" />
      </geometry>
    </collision>
  </link>
  <joint name="left_hip_pitch" type="revolute">
    <origin
      xyz="0 0.1205 -0.098"
      rpy="0 0 0" />
    <parent
      link="robot_base" />
    <child
      link="left_hip_pitch_link" />
    <axis
      xyz="0 1 0" />
    <limit
      lower="-1.5708"
      upper="1.5708"
      effort="100.0"
      velocity="100.0" />
  </joint>
  <link name="left_knee_pitch_link">
    <inertial>
      <origin
        xyz="-0.0370926236175317 -0.0102935438956814 -0.118658382266885"
        rpy="0 0 0" />
      <mass
        value="0.758037246379501" />
      <inertia
        ixx="0.00391729912353151"
        ixy="-2.7494582745576E-09"
        ixz="-7.97158747603537E-15"
        iyy="0.00469716796826954"
        iyz="0.000585098298460312"
        izz="0.00138299752551484" />
    </inertial>
    <visual>
      <origin
        xyz="0 0 0"
        rpy="0 0 0" />
      <geometry>
        <mesh
          filename="package://jc04_desc/meshes/left_knee_pitch_link.STL" />
      </geometry>
      <material
        name="">
        <color
          rgba="0.898039215686275 0.917647058823529 0.929411764705882 1" />
      </material>
    </visual>
    <collision>
      <origin
        xyz="0 0 0"
        rpy="0 0 0" />
      <geometry>
        <mesh
          filename="package://jc04_desc/meshes/left_knee_pitch_link.STL" />
      </geometry>
    </collision>
  </link>
  <joint name="left_knee_pitch" type="revolute">
    <origin
      xyz="0 0.0025 -0.275"
      rpy="0 0 0" />
    <parent
      link="left_hip_pitch_link" />
    <child
      link="left_knee_pitch_link" />
    <axis
      xyz="0 -1 0" />
    <limit
      lower="-1.5708"
      upper="1.5708"
      effort="100.0"
      velocity="100.0" />
  </joint>
  <link name="left_driving_wheel">
    <inertial>
      <origin
        xyz="1.3910963880233E-07 -0.00094701426873621 3.53717497736383E-06"
        rpy="0 0 0" />
      <mass
        value="0.638655440332923" />
      <inertia
        ixx="0.00125776029366308"
        ixy="-1.01616021285817E-09"
        ixz="1.36649910906935E-10"
        iyy="0.00241337774863368"
        iyz="4.41959293914977E-08"
        izz="0.00125808821267324" />
    </inertial>
    <visual>
      <origin
        xyz="0 0 0"
        rpy="0 0 0" />
      <geometry>
        <mesh
          filename="package://jc04_desc/meshes/left_driving_wheel.STL" />
      </geometry>
      <material
        name="">
        <color
          rgba="0.792156862745098 0.819607843137255 0.933333333333333 1" />
      </material>
    </visual>
    <collision>
      <!-- <origin xyz="0 0 0" rpy="0 0 0" />
      <geometry>
        <mesh filename="package://jc04_desc/meshes/left_driving_wheel.STL" />
      </geometry> -->
      <origin xyz="0 0 0" rpy="-1.5708 0 0" />
      <geometry>
        <cylinder length="0.03" radius="0.09" />
      </geometry>
    </collision>
  </link>
  <joint name="left_wheel_joint" type="continuous">
    <origin
      xyz="0 -0.0087 -0.257"
      rpy="0 0 0" />
    <parent
      link="left_knee_pitch_link" />
    <child
      link="left_driving_wheel" />
    <axis
      xyz="0 1 0" />
    <limit
      effort="100.0"
      velocity="100.0" />
  </joint>

  <link name="left_assist_wheel">
    <inertial>
      <origin
        xyz="-2.45844096191661E-07 9.7930785702971E-09 -3.0890970941222E-06"
        rpy="0 0 0" />
      <mass
        value="0.279818885469911" />
      <inertia
        ixx="0.000330074144114901"
        ixy="-3.33294822337154E-09"
        ixz="2.5938523861726E-09"
        iyy="0.000573286878995534"
        iyz="2.69895764157846E-10"
        izz="0.000330039476418042" />
    </inertial>
    <visual>
      <origin
        xyz="0 0 0"
        rpy="0 0 0" />
      <geometry>
        <mesh
          filename="package://jc04_desc/meshes/left_assist_wheel.STL" />
      </geometry>
      <material
        name="">
        <color
          rgba="0.752941176470588 0.752941176470588 0.752941176470588 1" />
      </material>
    </visual>
    <collision>
      <!-- <origin xyz="0 0 0" rpy="0 0 0" />
      <geometry>
        <mesh filename="package://jc04_desc/meshes/left_assist_wheel.STL" />
      </geometry> -->
      <origin xyz="0 0 0" rpy="-1.5708 0 0" />
      <geometry>
        <cylinder length="0.044" radius="0.063" />
      </geometry>
    </collision>
  </link>
  <joint name="left_assist" type="fixed">
    <origin
      xyz="-0.2 -0.011 -0.13951"
      rpy="0 0 0" />
    <parent
      link="left_knee_pitch_link" />
    <child
      link="left_assist_wheel" />
    <axis
      xyz="0 0 0" />
  </joint>
  <link name="left_knee_pitch_casing_link">
    <inertial>
      <origin
        xyz="-0.0430220609840743 -0.00854452769163563 -0.153608854930327"
        rpy="0 0 0" />
      <mass
        value="1.41954684124384" />
      <inertia
        ixx="0.00957400202828083"
        ixy="1.76251728211598E-05"
        ixz="0.000918423230199812"
        iyy="0.0151507821466897"
        iyz="-3.94607094339037E-05"
        izz="0.00623538041859044" />
    </inertial>
    <visual>
      <origin
        xyz="0 0 0"
        rpy="0 0 0" />
      <geometry>
        <mesh
          filename="package://jc04_desc/meshes/left_knee_pitch_casing_link.STL" />
      </geometry>
      <material
        name="">
        <color
          rgba="0.698039215686274 0.698039215686274 0.698039215686274 1" />
      </material>
    </visual>
    <collision>
      <origin
        xyz="0 0 0"
        rpy="0 0 0" />
      <geometry>
        <mesh
          filename="package://jc04_desc/meshes/left_knee_pitch_casing_link.STL" />
      </geometry>
    </collision>
  </link>
  <joint name="left_knee_pitch_casing_joint" type="fixed">
    <origin
      xyz="0 0 0"
      rpy="0 0 0" />
    <parent
      link="left_knee_pitch_link" />
    <child
      link="left_knee_pitch_casing_link" />
    <axis
      xyz="0 0 0" />
  </joint>


  <link name="right_shoulder_pitch_link">
    <inertial>
      <origin
        xyz="-0.000473097686282468 1.45916151569891E-06 0.0819622094560852"
        rpy="0 0 0" />
      <mass
        value="0.414919145489941" />
      <inertia
        ixx="0.000217064056966685"
        ixy="-4.25752984038187E-09"
        ixz="-1.55304093438243E-05"
        iyy="0.000220259242739327"
        iyz="1.86114889180266E-08"
        izz="0.000184171265304762" />
    </inertial>
    <visual>
      <origin
        xyz="0 0 0"
        rpy="0 0 0" />
      <geometry>
        <mesh
          filename="package://jc04_desc/meshes/right_shoulder_pitch_link.STL" />
      </geometry>
      <material
        name="">
        <color
          rgba="0.792156862745098 0.819607843137255 0.933333333333333 1" />
      </material>
    </visual>
    <collision>
      <origin
        xyz="0 0 0"
        rpy="0 0 0" />
      <geometry>
        <mesh
          filename="package://jc04_desc/meshes/right_shoulder_pitch_link.STL" />
      </geometry>
    </collision>
  </link>
  <joint name="right_shoulder_pitch" type="revolute">
    <origin
      xyz="0 -0.141 0.096"
      rpy="1.5708 0 0" />
    <parent
      link="robot_base" />
    <child
      link="right_shoulder_pitch_link" />
    <axis
      xyz="0 0 1" />
    <limit
      lower="-3.1416"
      upper="3.1416"
      effort="100.0"
      velocity="100.0" />
  </joint>
  <link name="right_shoulder_roll_link">
    <inertial>
      <origin
        xyz="-0.18187 0.0065724 -0.018318"
        rpy="0 0 0" />
      <mass
        value="0.51117" />
      <inertia
        ixx="0.00020874"
        ixy="4.4018E-05"
        ixz="7.2274E-05"
        iyy="0.00097204"
        iyz="9.8661E-06"
        izz="0.00097564" />
    </inertial>
    <visual>
      <origin
        xyz="0 0 0"
        rpy="0 0 0" />
      <geometry>
        <mesh
          filename="package://jc04_desc/meshes/right_shoulder_roll_link.STL" />
      </geometry>
      <material
        name="">
        <color
          rgba="0.89804 0.91765 0.92941 1" />
      </material>
    </visual>
    <collision>
      <origin
        xyz="0 0 0"
        rpy="0 0 0" />
      <geometry>
        <mesh
          filename="package://jc04_desc/meshes/right_shoulder_roll_link.STL" />
      </geometry>
    </collision>
  </link>
  <joint name="right_shoulder_roll" type="revolute">
    <origin
      xyz="-0.026 0 0.09"
      rpy="-1.5708 0 1.5708" />
    <parent
      link="right_shoulder_pitch_link" />
    <child
      link="right_shoulder_roll_link" />
    <axis
      xyz="0 0 1" />
    <limit
      lower="0"
      upper="3.1416"
      effort="100.0"
      velocity="100.0" />
  </joint>
  <link name="right_elbow_pitch_link">
    <inertial>
      <origin
        xyz="1.8418E-08 0.10575 0.0022495"
        rpy="0 0 0" />
      <mass
        value="0.098424" />
      <inertia
        ixx="0.0005063"
        ixy="-1.0901E-10"
        ixz="-4.6509E-12"
        iyy="2.1494E-05"
        iyz="-2.0282E-05"
        izz="0.00051921" />
    </inertial>
    <visual>
      <origin
        xyz="0 0 0"
        rpy="0 0 0" />
      <geometry>
        <mesh
          filename="package://jc04_desc/meshes/right_elbow_pitch_link.STL" />
      </geometry>
      <material
        name="">
        <color
          rgba="0.89804 0.91765 0.92941 1" />
      </material>
    </visual>
    <collision>
      <origin
        xyz="0 0 0"
        rpy="0 0 0" />
      <geometry>
        <mesh
          filename="package://jc04_desc/meshes/right_elbow_pitch_link.STL" />
      </geometry>
    </collision>
  </link>
  <joint name="right_elbow_pitch" type="revolute">
    <origin
      xyz="-0.21 -0.0155 -0.025"
      rpy="1.5708 -1.5708 0" />
    <parent
      link="right_shoulder_roll_link" />
    <child
      link="right_elbow_pitch_link" />
    <axis
      xyz="0 0 1" />
    <limit
      lower="-1.5708"
      upper="2.3562"
      effort="100.0"
      velocity="100.0" />
  </joint>

  <link name="right_elbow_pitch_casing_link">
    <inertial>
      <origin
        xyz="0.000106545583205655 0.100926504087859 -0.0199983483093895"
        rpy="0 0 0" />
      <mass
        value="0.727558230344206" />
      <inertia
        ixx="0.00294962257984688"
        ixy="-1.87001061338041E-05"
        ixz="5.97725023005196E-07"
        iyy="0.0007256300835957"
        iyz="0.000166637302564913"
        izz="0.00324010404488832" />
    </inertial>
    <visual>
      <origin
        xyz="0 0 0"
        rpy="0 0 0" />
      <geometry>
        <mesh
          filename="package://jc04_desc/meshes/right_elbow_pitch_casing_link.STL" />
      </geometry>
      <material
        name="">
        <color
          rgba="0.698039215686274 0.698039215686274 0.698039215686274 1" />
      </material>
    </visual>
    <collision>
      <origin
        xyz="0 0 0"
        rpy="0 0 0" />
      <geometry>
        <mesh
          filename="package://jc04_desc/meshes/right_elbow_pitch_casing_link.STL" />
      </geometry>
    </collision>
  </link>
  <joint name="right_elbow_pitch_casing_joint" type="fixed">
    <origin
      xyz="0 0 0"
      rpy="0 0 0" />
    <parent
      link="right_elbow_pitch_link" />
    <child
      link="right_elbow_pitch_casing_link" />
    <axis
      xyz="0 0 0" />
  </joint>
  <link name="right_gripper">
    <inertial>
      <origin
        xyz="-0.0449643854633953 -0.00541614766194809 -2.17842935790885E-09"
        rpy="0 0 0" />
      <mass
        value="0.10362006196229" />
      <inertia
        ixx="2.52508778519405E-05"
        ixy="7.96888228939716E-06"
        ixz="5.04561240475711E-11"
        iyy="0.000211227480909283"
        iyz="-8.0786422329489E-12"
        izz="0.000206602596755285" />
    </inertial>
    <visual>
      <origin
        xyz="0 0 0"
        rpy="0 0 0" />
      <geometry>
        <mesh
          filename="package://jc04_desc/meshes/right_gripper.STL" />
      </geometry>
      <material
        name="">
        <color
          rgba="0.384313725490196 0.384313725490196 0.384313725490196 1" />
      </material>
    </visual>
    <collision>
      <origin
        xyz="0 0 0"
        rpy="0 0 0" />
      <geometry>
        <mesh
          filename="package://jc04_desc/meshes/right_gripper.STL" />
      </geometry>
    </collision>
  </link>
  <joint name="right_gripper_joint" type="fixed">
    <origin
      xyz="0 0.22964 -0.012"
      rpy="-1.5708 0 1.5708" />
    <parent
      link="right_elbow_pitch_link" />
    <child
      link="right_gripper" />
    <axis
      xyz="0 0 0" />
  </joint>


  <link name="left_shoulder_pitch_link">
    <inertial>
      <origin
        xyz="-0.000473097686283471 -1.45916151716996E-06 -0.0819622094560845"
        rpy="0 0 0" />
      <mass
        value="0.414919145489942" />
      <inertia
        ixx="0.000217064056966685"
        ixy="4.25752984034421E-09"
        ixz="1.55304093438243E-05"
        iyy="0.000220259242739327"
        iyz="1.86114889179452E-08"
        izz="0.000184171265304762" />
    </inertial>
    <visual>
      <origin
        xyz="0 0 0"
        rpy="0 0 0" />
      <geometry>
        <mesh
          filename="package://jc04_desc/meshes/left_shoulder_pitch_link.STL" />
      </geometry>
      <material
        name="">
        <color
          rgba="0.792156862745098 0.819607843137255 0.933333333333333 1" />
      </material>
    </visual>
    <collision>
      <origin
        xyz="0 0 0"
        rpy="0 0 0" />
      <geometry>
        <mesh
          filename="package://jc04_desc/meshes/left_shoulder_pitch_link.STL" />
      </geometry>
    </collision>

  </link>
  <joint name="left_shoulder_pitch" type="revolute">
    <origin
      xyz="0 0.141 0.096"
      rpy="1.5707963267949 0 0" />
    <parent
      link="robot_base" />
    <child
      link="left_shoulder_pitch_link" />
    <axis
      xyz="0 0 1" />
    <limit
      lower="-3.1416"
      upper="3.1416"
      effort="100.0"
      velocity="100.0" />
  </joint>
  <link name="left_shoulder_roll_link">
    <inertial>
      <origin
        xyz="-0.18187 -0.0065724 -0.018318"
        rpy="0 0 0" />
      <mass
        value="0.51117" />
      <inertia
        ixx="0.00020874"
        ixy="-4.4018E-05"
        ixz="7.2235E-05"
        iyy="0.00097204"
        iyz="-9.8661E-06"
        izz="0.00097564" />
    </inertial>
    <visual>
      <origin
        xyz="0 0 0"
        rpy="0 0 0" />
      <geometry>
        <mesh
          filename="package://jc04_desc/meshes/left_shoulder_roll_link.STL" />
      </geometry>
      <material
        name="">
        <color
          rgba="0.86667 0.86667 0.8902 1" />
      </material>
    </visual>
    <collision>
      <origin
        xyz="0 0 0"
        rpy="0 0 0" />
      <geometry>
        <mesh
          filename="package://jc04_desc/meshes/left_shoulder_roll_link.STL" />
      </geometry>
    </collision>
  </link>
  <joint name="left_shoulder_roll" type="revolute">
    <origin
      xyz="-0.026 0 -0.09"
      rpy="-1.5708 0 1.5708" />
    <parent
      link="left_shoulder_pitch_link" />
    <child
      link="left_shoulder_roll_link" />
    <axis
      xyz="0 0 -1" />
    <limit
      lower="0"
      upper="3.1416"
      effort="100.0"
      velocity="100.0" />
  </joint>
  <link name="left_elbow_pitch_link">
    <inertial>
      <origin
        xyz="-1.8418E-08 0.10575 -0.0022495"
        rpy="0 0 0" />
      <mass
        value="0.098424" />
      <inertia
        ixx="0.0005063"
        ixy="1.0901E-10"
        ixz="-4.6509E-12"
        iyy="2.1494E-05"
        iyz="2.0282E-05"
        izz="0.00051921" />
    </inertial>
    <visual>
      <origin
        xyz="0 0 0"
        rpy="0 0 0" />
      <geometry>
        <mesh
          filename="package://jc04_desc/meshes/left_elbow_pitch_link.STL" />
      </geometry>
      <material
        name="">
        <color
          rgba="0.89804 0.91765 0.92941 1" />
      </material>
    </visual>
    <collision>
      <origin
        xyz="0 0 0"
        rpy="0 0 0" />
      <geometry>
        <mesh
          filename="package://jc04_desc/meshes/left_elbow_pitch_link.STL" />
      </geometry>
    </collision>
  </link>
  <joint name="left_elbow_pitch" type="revolute">
    <origin
      xyz="-0.21 0.0155 -0.025"
      rpy="1.5708 -1.5708 0" />
    <parent
      link="left_shoulder_roll_link" />
    <child
      link="left_elbow_pitch_link" />
    <axis
      xyz="0 0 1" />
    <limit
      lower="-1.5708"
      upper="2.3562"
      effort="100.0"
      velocity="100.0" />
  </joint>

  <link name="left_elbow_pitch_casing_link">
    <inertial>
      <origin
        xyz="0.000106802911734415 0.100932144191984 0.0199958767594479"
        rpy="0 0 0" />
      <mass
        value="0.727666303151002" />
      <inertia
        ixx="0.00294986839277408"
        ixy="-1.87574522887551E-05"
        ixz="-6.32401090029057E-07"
        iyy="0.000725667115743847"
        iyz="-0.000166651156958227"
        izz="0.00324037314461369" />
    </inertial>
    <visual>
      <origin
        xyz="0 0 0"
        rpy="0 0 0" />
      <geometry>
        <mesh
          filename="package://jc04_desc/meshes/left_elbow_pitch_casing_link.STL" />
      </geometry>
      <material
        name="">
        <color
          rgba="0.698039215686274 0.698039215686274 0.698039215686274 1" />
      </material>
    </visual>
    <collision>
      <origin
        xyz="0 0 0"
        rpy="0 0 0" />
      <geometry>
        <mesh
          filename="package://jc04_desc/meshes/left_elbow_pitch_casing_link.STL" />
      </geometry>
    </collision>
  </link>
  <joint name="left_elbow_pitch_casing_joint" type="fixed">
    <origin
      xyz="0 0 0"
      rpy="0 0 0" />
    <parent
      link="left_elbow_pitch_link" />
    <child
      link="left_elbow_pitch_casing_link" />
    <axis
      xyz="0 0 0" />
  </joint>
  <link name="left_gripper">
    <inertial>
      <origin
        xyz="-0.0449643854633952 0.00541614766194815 2.17842934901839E-09"
        rpy="0 0 0" />
      <mass
        value="0.10362006196229" />
      <inertia
        ixx="2.52508778519405E-05"
        ixy="-7.96888228939716E-06"
        ixz="-5.04561240513148E-11"
        iyy="0.000211227480909283"
        iyz="-8.07864221529948E-12"
        izz="0.000206602596755285" />
    </inertial>
    <visual>
      <origin
        xyz="0 0 0"
        rpy="0 0 0" />
      <geometry>
        <mesh
          filename="package://jc04_desc/meshes/left_gripper.STL" />
      </geometry>
      <material
        name="">
        <color
          rgba="0.384313725490196 0.384313725490196 0.384313725490196 1" />
      </material>
    </visual>
    <collision>
      <origin
        xyz="0 0 0"
        rpy="0 0 0" />
      <geometry>
        <mesh
          filename="package://jc04_desc/meshes/left_gripper.STL" />
      </geometry>
    </collision>
  </link>
  <joint name="left_gripper_joint" type="fixed">
    <origin
      xyz="0 0.22964 0.012"
      rpy="-1.5708 0 1.5708" />
    <parent
      link="left_elbow_pitch_link" />
    <child
      link="left_gripper" />
    <axis
      xyz="0 0 0" />
  </joint>


</robot>